[2023-06-14T12:56:16.792+0000] {taskinstance.py:1083} INFO - Dependencies all met for <TaskInstance: ETL_psql_redshift_dag.Load_to_psql manual__2023-06-14T12:48:00.304587+00:00 [queued]>
[2023-06-14T12:56:16.799+0000] {taskinstance.py:1083} INFO - Dependencies all met for <TaskInstance: ETL_psql_redshift_dag.Load_to_psql manual__2023-06-14T12:48:00.304587+00:00 [queued]>
[2023-06-14T12:56:16.799+0000] {taskinstance.py:1279} INFO - 
--------------------------------------------------------------------------------
[2023-06-14T12:56:16.800+0000] {taskinstance.py:1280} INFO - Starting attempt 3 of 3
[2023-06-14T12:56:16.800+0000] {taskinstance.py:1281} INFO - 
--------------------------------------------------------------------------------
[2023-06-14T12:56:16.808+0000] {taskinstance.py:1300} INFO - Executing <Task(PythonOperator): Load_to_psql> on 2023-06-14 12:48:00.304587+00:00
[2023-06-14T12:56:16.813+0000] {standard_task_runner.py:55} INFO - Started process 540 to run task
[2023-06-14T12:56:16.817+0000] {standard_task_runner.py:82} INFO - Running: ['***', 'tasks', 'run', 'ETL_psql_redshift_dag', 'Load_to_psql', 'manual__2023-06-14T12:48:00.304587+00:00', '--job-id', '21', '--raw', '--subdir', 'DAGS_FOLDER/dags_setup.py', '--cfg-path', '/tmp/tmp73jkhbrz']
[2023-06-14T12:56:16.819+0000] {standard_task_runner.py:83} INFO - Job 21: Subtask Load_to_psql
[2023-06-14T12:56:16.894+0000] {task_command.py:388} INFO - Running <TaskInstance: ETL_psql_redshift_dag.Load_to_psql manual__2023-06-14T12:48:00.304587+00:00 [running]> on host 3d4df578486c
[2023-06-14T12:56:16.958+0000] {taskinstance.py:1509} INFO - Exporting the following env vars:
AIRFLOW_CTX_DAG_OWNER=vupham
AIRFLOW_CTX_DAG_ID=ETL_psql_redshift_dag
AIRFLOW_CTX_TASK_ID=Load_to_psql
AIRFLOW_CTX_EXECUTION_DATE=2023-06-14T12:48:00.304587+00:00
AIRFLOW_CTX_TRY_NUMBER=3
AIRFLOW_CTX_DAG_RUN_ID=manual__2023-06-14T12:48:00.304587+00:00
[2023-06-14T12:56:17.077+0000] {taskinstance.py:1768} ERROR - Task failed with exception
Traceback (most recent call last):
  File "/home/airflow/.local/lib/python3.7/site-packages/airflow/operators/python.py", line 175, in execute
    return_value = self.execute_callable()
  File "/home/airflow/.local/lib/python3.7/site-packages/airflow/operators/python.py", line 192, in execute_callable
    return self.python_callable(*self.op_args, **self.op_kwargs)
  File "/opt/airflow/dags/ETL_psql/Load/Load_psql.py", line 53, in Load_schema
    Load_table(f"Sale_schema.{table}", df, cur);
  File "/opt/airflow/dags/ETL_psql/Load/Load_psql.py", line 23, in Load_table
    cur.executemany(query, records);
psycopg2.errors.UniqueViolation: duplicate key value violates unique constraint "locations_pkey"
DETAIL:  Key (postal_code)=(39980) already exists.

[2023-06-14T12:56:17.094+0000] {taskinstance.py:1323} INFO - Marking task as FAILED. dag_id=ETL_psql_redshift_dag, task_id=Load_to_psql, execution_date=20230614T124800, start_date=20230614T125616, end_date=20230614T125617
[2023-06-14T12:56:17.104+0000] {standard_task_runner.py:105} ERROR - Failed to execute job 21 for task Load_to_psql (duplicate key value violates unique constraint "locations_pkey"
DETAIL:  Key (postal_code)=(39980) already exists.
; 540)
[2023-06-14T12:56:17.152+0000] {local_task_job.py:208} INFO - Task exited with return code 1
[2023-06-14T12:56:17.172+0000] {taskinstance.py:2578} INFO - 0 downstream tasks scheduled from follow-on schedule check
