[2023-06-14T09:16:30.494+0000] {taskinstance.py:1083} INFO - Dependencies all met for <TaskInstance: ETL_psql_redshift_dag.Create_redshift_schema manual__2023-06-14T09:10:10.647035+00:00 [queued]>
[2023-06-14T09:16:30.501+0000] {taskinstance.py:1083} INFO - Dependencies all met for <TaskInstance: ETL_psql_redshift_dag.Create_redshift_schema manual__2023-06-14T09:10:10.647035+00:00 [queued]>
[2023-06-14T09:16:30.502+0000] {taskinstance.py:1279} INFO - 
--------------------------------------------------------------------------------
[2023-06-14T09:16:30.503+0000] {taskinstance.py:1280} INFO - Starting attempt 1 of 3
[2023-06-14T09:16:30.503+0000] {taskinstance.py:1281} INFO - 
--------------------------------------------------------------------------------
[2023-06-14T09:16:30.510+0000] {taskinstance.py:1300} INFO - Executing <Task(PythonOperator): Create_redshift_schema> on 2023-06-14 09:10:10.647035+00:00
[2023-06-14T09:16:30.516+0000] {standard_task_runner.py:55} INFO - Started process 454 to run task
[2023-06-14T09:16:30.520+0000] {standard_task_runner.py:82} INFO - Running: ['***', 'tasks', 'run', 'ETL_psql_redshift_dag', 'Create_redshift_schema', 'manual__2023-06-14T09:10:10.647035+00:00', '--job-id', '22', '--raw', '--subdir', 'DAGS_FOLDER/dags_setup.py', '--cfg-path', '/tmp/tmp1cgn7fma']
[2023-06-14T09:16:30.522+0000] {standard_task_runner.py:83} INFO - Job 22: Subtask Create_redshift_schema
[2023-06-14T09:16:30.582+0000] {task_command.py:388} INFO - Running <TaskInstance: ETL_psql_redshift_dag.Create_redshift_schema manual__2023-06-14T09:10:10.647035+00:00 [running]> on host f2da7a3b6ffa
[2023-06-14T09:16:30.630+0000] {taskinstance.py:1509} INFO - Exporting the following env vars:
AIRFLOW_CTX_DAG_OWNER=vupham
AIRFLOW_CTX_DAG_ID=ETL_psql_redshift_dag
AIRFLOW_CTX_TASK_ID=Create_redshift_schema
AIRFLOW_CTX_EXECUTION_DATE=2023-06-14T09:10:10.647035+00:00
AIRFLOW_CTX_TRY_NUMBER=1
AIRFLOW_CTX_DAG_RUN_ID=manual__2023-06-14T09:10:10.647035+00:00
[2023-06-14T09:16:31.069+0000] {iam_helper.py:359} ERROR - ClientError: An error occurred (ClusterNotFound) when calling the DescribeClusters operation: Cluster vupham-redshift-cluster not found.
[2023-06-14T09:16:31.071+0000] {taskinstance.py:1768} ERROR - Task failed with exception
Traceback (most recent call last):
  File "/home/airflow/.local/lib/python3.7/site-packages/airflow/operators/python.py", line 175, in execute
    return_value = self.execute_callable()
  File "/home/airflow/.local/lib/python3.7/site-packages/airflow/operators/python.py", line 192, in execute_callable
    return self.python_callable(*self.op_args, **self.op_kwargs)
  File "/opt/airflow/dags/ETL_redshift/Load_s3_to_redshift.py", line 21, in Create_redshift_schema
    conn = Establish_redshift_connection();
  File "/opt/airflow/dags/ETL_redshift/Load_s3_to_redshift.py", line 13, in Establish_redshift_connection
    region = 'ap-southeast-1'
  File "/home/airflow/.local/lib/python3.7/site-packages/redshift_connector/__init__.py", line 332, in connect
    IamHelper.set_iam_properties(info)
  File "/home/airflow/.local/lib/python3.7/site-packages/redshift_connector/iam_helper.py", line 116, in set_iam_properties
    IamHelper.set_iam_credentials(info)
  File "/home/airflow/.local/lib/python3.7/site-packages/redshift_connector/iam_helper.py", line 176, in set_iam_credentials
    IamHelper.set_cluster_credentials(provider, info)
  File "/home/airflow/.local/lib/python3.7/site-packages/redshift_connector/iam_helper.py", line 360, in set_cluster_credentials
    raise e
  File "/home/airflow/.local/lib/python3.7/site-packages/redshift_connector/iam_helper.py", line 282, in set_cluster_credentials
    response = client.describe_clusters(ClusterIdentifier=info.cluster_identifier)
  File "/home/airflow/.local/lib/python3.7/site-packages/botocore/client.py", line 530, in _api_call
    return self._make_api_call(operation_name, kwargs)
  File "/home/airflow/.local/lib/python3.7/site-packages/botocore/client.py", line 964, in _make_api_call
    raise error_class(parsed_response, operation_name)
botocore.errorfactory.ClusterNotFoundFault: An error occurred (ClusterNotFound) when calling the DescribeClusters operation: Cluster vupham-redshift-cluster not found.
[2023-06-14T09:16:31.091+0000] {taskinstance.py:1323} INFO - Marking task as UP_FOR_RETRY. dag_id=ETL_psql_redshift_dag, task_id=Create_redshift_schema, execution_date=20230614T091010, start_date=20230614T091630, end_date=20230614T091631
[2023-06-14T09:16:31.104+0000] {standard_task_runner.py:105} ERROR - Failed to execute job 22 for task Create_redshift_schema (An error occurred (ClusterNotFound) when calling the DescribeClusters operation: Cluster vupham-redshift-cluster not found.; 454)
[2023-06-14T09:16:31.157+0000] {local_task_job.py:208} INFO - Task exited with return code 1
[2023-06-14T09:16:31.175+0000] {taskinstance.py:2578} INFO - 0 downstream tasks scheduled from follow-on schedule check
