[2023-06-13T14:44:58.832+0000] {taskinstance.py:1083} INFO - Dependencies all met for <TaskInstance: ETL_psql_redshift_dag.Load_to_psql manual__2023-06-13T14:44:40.914207+00:00 [queued]>
[2023-06-13T14:44:58.837+0000] {taskinstance.py:1083} INFO - Dependencies all met for <TaskInstance: ETL_psql_redshift_dag.Load_to_psql manual__2023-06-13T14:44:40.914207+00:00 [queued]>
[2023-06-13T14:44:58.838+0000] {taskinstance.py:1279} INFO - 
--------------------------------------------------------------------------------
[2023-06-13T14:44:58.838+0000] {taskinstance.py:1280} INFO - Starting attempt 1 of 3
[2023-06-13T14:44:58.839+0000] {taskinstance.py:1281} INFO - 
--------------------------------------------------------------------------------
[2023-06-13T14:44:58.846+0000] {taskinstance.py:1300} INFO - Executing <Task(PythonOperator): Load_to_psql> on 2023-06-13 14:44:40.914207+00:00
[2023-06-13T14:44:58.850+0000] {standard_task_runner.py:55} INFO - Started process 315 to run task
[2023-06-13T14:44:58.853+0000] {standard_task_runner.py:82} INFO - Running: ['***', 'tasks', 'run', 'ETL_psql_redshift_dag', 'Load_to_psql', 'manual__2023-06-13T14:44:40.914207+00:00', '--job-id', '16', '--raw', '--subdir', 'DAGS_FOLDER/dags_setup.py', '--cfg-path', '/tmp/tmpyd5lg4f_']
[2023-06-13T14:44:58.855+0000] {standard_task_runner.py:83} INFO - Job 16: Subtask Load_to_psql
[2023-06-13T14:44:58.904+0000] {task_command.py:388} INFO - Running <TaskInstance: ETL_psql_redshift_dag.Load_to_psql manual__2023-06-13T14:44:40.914207+00:00 [running]> on host 63f0fed3274d
[2023-06-13T14:44:58.949+0000] {taskinstance.py:1509} INFO - Exporting the following env vars:
AIRFLOW_CTX_DAG_OWNER=vupham
AIRFLOW_CTX_DAG_ID=ETL_psql_redshift_dag
AIRFLOW_CTX_TASK_ID=Load_to_psql
AIRFLOW_CTX_EXECUTION_DATE=2023-06-13T14:44:40.914207+00:00
AIRFLOW_CTX_TRY_NUMBER=1
AIRFLOW_CTX_DAG_RUN_ID=manual__2023-06-13T14:44:40.914207+00:00
[2023-06-13T14:44:58.953+0000] {taskinstance.py:1768} ERROR - Task failed with exception
Traceback (most recent call last):
  File "/home/airflow/.local/lib/python3.7/site-packages/airflow/operators/python.py", line 175, in execute
    return_value = self.execute_callable()
  File "/home/airflow/.local/lib/python3.7/site-packages/airflow/operators/python.py", line 192, in execute_callable
    return self.python_callable(*self.op_args, **self.op_kwargs)
  File "/opt/airflow/dags/ETL_psql/Load/Load_psql.py", line 38, in Load_schema
    conn = psycopg2.connect(**connect_params); # Connect
  File "/home/airflow/.local/lib/python3.7/site-packages/psycopg2/__init__.py", line 122, in connect
    conn = _connect(dsn, connection_factory=connection_factory, **kwasync)
psycopg2.OperationalError: connection to server at "postgres" (192.168.96.2), port 5432 failed: FATAL:  database "sale_db" does not exist

[2023-06-13T14:44:58.961+0000] {taskinstance.py:1323} INFO - Marking task as UP_FOR_RETRY. dag_id=ETL_psql_redshift_dag, task_id=Load_to_psql, execution_date=20230613T144440, start_date=20230613T144458, end_date=20230613T144458
[2023-06-13T14:44:58.968+0000] {standard_task_runner.py:105} ERROR - Failed to execute job 16 for task Load_to_psql (connection to server at "postgres" (192.168.96.2), port 5432 failed: FATAL:  database "sale_db" does not exist
; 315)
[2023-06-13T14:44:58.985+0000] {local_task_job.py:208} INFO - Task exited with return code 1
[2023-06-13T14:44:59.002+0000] {taskinstance.py:2578} INFO - 0 downstream tasks scheduled from follow-on schedule check
