[2023-06-14T09:10:56.803+0000] {taskinstance.py:1083} INFO - Dependencies all met for <TaskInstance: ETL_psql_redshift_dag.Transform_shipment_df scheduled__2023-06-13T00:00:00+00:00 [queued]>
[2023-06-14T09:10:56.843+0000] {taskinstance.py:1083} INFO - Dependencies all met for <TaskInstance: ETL_psql_redshift_dag.Transform_shipment_df scheduled__2023-06-13T00:00:00+00:00 [queued]>
[2023-06-14T09:10:56.845+0000] {taskinstance.py:1279} INFO - 
--------------------------------------------------------------------------------
[2023-06-14T09:10:56.846+0000] {taskinstance.py:1280} INFO - Starting attempt 1 of 3
[2023-06-14T09:10:56.853+0000] {taskinstance.py:1281} INFO - 
--------------------------------------------------------------------------------
[2023-06-14T09:10:56.912+0000] {taskinstance.py:1300} INFO - Executing <Task(PythonOperator): Transform_shipment_df> on 2023-06-13 00:00:00+00:00
[2023-06-14T09:10:56.930+0000] {standard_task_runner.py:55} INFO - Started process 316 to run task
[2023-06-14T09:10:56.939+0000] {standard_task_runner.py:82} INFO - Running: ['***', 'tasks', 'run', 'ETL_psql_redshift_dag', 'Transform_shipment_df', 'scheduled__2023-06-13T00:00:00+00:00', '--job-id', '10', '--raw', '--subdir', 'DAGS_FOLDER/dags_setup.py', '--cfg-path', '/tmp/tmpuwm8fh9t']
[2023-06-14T09:10:56.953+0000] {standard_task_runner.py:83} INFO - Job 10: Subtask Transform_shipment_df
[2023-06-14T09:10:57.308+0000] {task_command.py:388} INFO - Running <TaskInstance: ETL_psql_redshift_dag.Transform_shipment_df scheduled__2023-06-13T00:00:00+00:00 [running]> on host f2da7a3b6ffa
[2023-06-14T09:10:57.432+0000] {taskinstance.py:1509} INFO - Exporting the following env vars:
AIRFLOW_CTX_DAG_OWNER=vupham
AIRFLOW_CTX_DAG_ID=ETL_psql_redshift_dag
AIRFLOW_CTX_TASK_ID=Transform_shipment_df
AIRFLOW_CTX_EXECUTION_DATE=2023-06-13T00:00:00+00:00
AIRFLOW_CTX_TRY_NUMBER=1
AIRFLOW_CTX_DAG_RUN_ID=scheduled__2023-06-13T00:00:00+00:00
[2023-06-14T09:11:00.079+0000] {taskinstance.py:1768} ERROR - Task failed with exception
Traceback (most recent call last):
  File "/home/airflow/.local/lib/python3.7/site-packages/pandas/core/indexes/base.py", line 3361, in get_loc
    return self._engine.get_loc(casted_key)
  File "pandas/_libs/index.pyx", line 76, in pandas._libs.index.IndexEngine.get_loc
  File "pandas/_libs/index.pyx", line 108, in pandas._libs.index.IndexEngine.get_loc
  File "pandas/_libs/hashtable_class_helper.pxi", line 5198, in pandas._libs.hashtable.PyObjectHashTable.get_item
  File "pandas/_libs/hashtable_class_helper.pxi", line 5206, in pandas._libs.hashtable.PyObjectHashTable.get_item
KeyError: 'Destination'

The above exception was the direct cause of the following exception:

Traceback (most recent call last):
  File "/home/airflow/.local/lib/python3.7/site-packages/airflow/operators/python.py", line 175, in execute
    return_value = self.execute_callable()
  File "/home/airflow/.local/lib/python3.7/site-packages/airflow/operators/python.py", line 192, in execute_callable
    return self.python_callable(*self.op_args, **self.op_kwargs)
  File "/opt/airflow/dags/ETL_psql/Transform/Transform_shipments.py", line 18, in Transform_shipments
    shipment = Transform_shipment_df(Name, filePath);
  File "/opt/airflow/dags/ETL_psql/Transform/Transform.py", line 22, in __init__
    self.transform();
  File "/opt/airflow/dags/ETL_psql/Transform/Transform_shipments.py", line 8, in transform
    self.df['Shipping address'] = [address.split(",")[0] for address in self.df['Destination']];
  File "/home/airflow/.local/lib/python3.7/site-packages/pandas/core/frame.py", line 3458, in __getitem__
    indexer = self.columns.get_loc(key)
  File "/home/airflow/.local/lib/python3.7/site-packages/pandas/core/indexes/base.py", line 3363, in get_loc
    raise KeyError(key) from err
KeyError: 'Destination'
[2023-06-14T09:11:00.103+0000] {taskinstance.py:1323} INFO - Marking task as UP_FOR_RETRY. dag_id=ETL_psql_redshift_dag, task_id=Transform_shipment_df, execution_date=20230613T000000, start_date=20230614T091056, end_date=20230614T091100
[2023-06-14T09:11:00.128+0000] {standard_task_runner.py:105} ERROR - Failed to execute job 10 for task Transform_shipment_df ('Destination'; 316)
[2023-06-14T09:11:00.166+0000] {local_task_job.py:208} INFO - Task exited with return code 1
[2023-06-14T09:11:00.223+0000] {taskinstance.py:2578} INFO - 0 downstream tasks scheduled from follow-on schedule check
