[2023-06-13T14:36:46.255+0000] {taskinstance.py:1083} INFO - Dependencies all met for <TaskInstance: ETL_psql_redshift_dag.Load_to_psql manual__2023-06-13T14:32:24.400985+00:00 [queued]>
[2023-06-13T14:36:46.261+0000] {taskinstance.py:1083} INFO - Dependencies all met for <TaskInstance: ETL_psql_redshift_dag.Load_to_psql manual__2023-06-13T14:32:24.400985+00:00 [queued]>
[2023-06-13T14:36:46.261+0000] {taskinstance.py:1279} INFO - 
--------------------------------------------------------------------------------
[2023-06-13T14:36:46.262+0000] {taskinstance.py:1280} INFO - Starting attempt 3 of 3
[2023-06-13T14:36:46.262+0000] {taskinstance.py:1281} INFO - 
--------------------------------------------------------------------------------
[2023-06-13T14:36:46.270+0000] {taskinstance.py:1300} INFO - Executing <Task(PythonOperator): Load_to_psql> on 2023-06-13 14:32:24.400985+00:00
[2023-06-13T14:36:46.275+0000] {standard_task_runner.py:55} INFO - Started process 372 to run task
[2023-06-13T14:36:46.279+0000] {standard_task_runner.py:82} INFO - Running: ['***', 'tasks', 'run', 'ETL_psql_redshift_dag', 'Load_to_psql', 'manual__2023-06-13T14:32:24.400985+00:00', '--job-id', '12', '--raw', '--subdir', 'DAGS_FOLDER/dags_setup.py', '--cfg-path', '/tmp/tmpcb167gag']
[2023-06-13T14:36:46.281+0000] {standard_task_runner.py:83} INFO - Job 12: Subtask Load_to_psql
[2023-06-13T14:36:46.341+0000] {task_command.py:388} INFO - Running <TaskInstance: ETL_psql_redshift_dag.Load_to_psql manual__2023-06-13T14:32:24.400985+00:00 [running]> on host dd24607af7ec
[2023-06-13T14:36:46.389+0000] {taskinstance.py:1509} INFO - Exporting the following env vars:
AIRFLOW_CTX_DAG_OWNER=vupham
AIRFLOW_CTX_DAG_ID=ETL_psql_redshift_dag
AIRFLOW_CTX_TASK_ID=Load_to_psql
AIRFLOW_CTX_EXECUTION_DATE=2023-06-13T14:32:24.400985+00:00
AIRFLOW_CTX_TRY_NUMBER=3
AIRFLOW_CTX_DAG_RUN_ID=manual__2023-06-13T14:32:24.400985+00:00
[2023-06-13T14:36:46.391+0000] {taskinstance.py:1768} ERROR - Task failed with exception
Traceback (most recent call last):
  File "/home/airflow/.local/lib/python3.7/site-packages/airflow/operators/python.py", line 175, in execute
    return_value = self.execute_callable()
  File "/home/airflow/.local/lib/python3.7/site-packages/airflow/operators/python.py", line 192, in execute_callable
    return self.python_callable(*self.op_args, **self.op_kwargs)
  File "/opt/airflow/dags/ETL_psql/Load/Load_psql.py", line 38, in Load_schema
    conn = psycopg2.connect(**connect_params); # Connect
  File "/home/airflow/.local/lib/python3.7/site-packages/psycopg2/__init__.py", line 122, in connect
    conn = _connect(dsn, connection_factory=connection_factory, **kwasync)
psycopg2.OperationalError: connection to server at "localhost" (127.0.0.1), port 5432 failed: Connection refused
	Is the server running on that host and accepting TCP/IP connections?
connection to server at "localhost" (::1), port 5432 failed: Cannot assign requested address
	Is the server running on that host and accepting TCP/IP connections?

[2023-06-13T14:36:46.400+0000] {taskinstance.py:1323} INFO - Marking task as FAILED. dag_id=ETL_psql_redshift_dag, task_id=Load_to_psql, execution_date=20230613T143224, start_date=20230613T143646, end_date=20230613T143646
[2023-06-13T14:36:46.406+0000] {standard_task_runner.py:105} ERROR - Failed to execute job 12 for task Load_to_psql (connection to server at "localhost" (127.0.0.1), port 5432 failed: Connection refused
	Is the server running on that host and accepting TCP/IP connections?
connection to server at "localhost" (::1), port 5432 failed: Cannot assign requested address
	Is the server running on that host and accepting TCP/IP connections?
; 372)
[2023-06-13T14:36:46.453+0000] {local_task_job.py:208} INFO - Task exited with return code 1
[2023-06-13T14:36:46.471+0000] {taskinstance.py:2578} INFO - 0 downstream tasks scheduled from follow-on schedule check
