[2023-06-13T14:32:43.991+0000] {taskinstance.py:1083} INFO - Dependencies all met for <TaskInstance: ETL_psql_redshift_dag.Load_to_psql manual__2023-06-13T14:32:24.400985+00:00 [queued]>
[2023-06-13T14:32:43.997+0000] {taskinstance.py:1083} INFO - Dependencies all met for <TaskInstance: ETL_psql_redshift_dag.Load_to_psql manual__2023-06-13T14:32:24.400985+00:00 [queued]>
[2023-06-13T14:32:43.998+0000] {taskinstance.py:1279} INFO - 
--------------------------------------------------------------------------------
[2023-06-13T14:32:43.998+0000] {taskinstance.py:1280} INFO - Starting attempt 1 of 3
[2023-06-13T14:32:43.999+0000] {taskinstance.py:1281} INFO - 
--------------------------------------------------------------------------------
[2023-06-13T14:32:44.006+0000] {taskinstance.py:1300} INFO - Executing <Task(PythonOperator): Load_to_psql> on 2023-06-13 14:32:24.400985+00:00
[2023-06-13T14:32:44.011+0000] {standard_task_runner.py:55} INFO - Started process 318 to run task
[2023-06-13T14:32:44.015+0000] {standard_task_runner.py:82} INFO - Running: ['***', 'tasks', 'run', 'ETL_psql_redshift_dag', 'Load_to_psql', 'manual__2023-06-13T14:32:24.400985+00:00', '--job-id', '10', '--raw', '--subdir', 'DAGS_FOLDER/dags_setup.py', '--cfg-path', '/tmp/tmptu58equc']
[2023-06-13T14:32:44.018+0000] {standard_task_runner.py:83} INFO - Job 10: Subtask Load_to_psql
[2023-06-13T14:32:44.071+0000] {task_command.py:388} INFO - Running <TaskInstance: ETL_psql_redshift_dag.Load_to_psql manual__2023-06-13T14:32:24.400985+00:00 [running]> on host dd24607af7ec
[2023-06-13T14:32:44.115+0000] {taskinstance.py:1509} INFO - Exporting the following env vars:
AIRFLOW_CTX_DAG_OWNER=vupham
AIRFLOW_CTX_DAG_ID=ETL_psql_redshift_dag
AIRFLOW_CTX_TASK_ID=Load_to_psql
AIRFLOW_CTX_EXECUTION_DATE=2023-06-13T14:32:24.400985+00:00
AIRFLOW_CTX_TRY_NUMBER=1
AIRFLOW_CTX_DAG_RUN_ID=manual__2023-06-13T14:32:24.400985+00:00
[2023-06-13T14:32:44.117+0000] {taskinstance.py:1768} ERROR - Task failed with exception
Traceback (most recent call last):
  File "/home/airflow/.local/lib/python3.7/site-packages/airflow/operators/python.py", line 175, in execute
    return_value = self.execute_callable()
  File "/home/airflow/.local/lib/python3.7/site-packages/airflow/operators/python.py", line 192, in execute_callable
    return self.python_callable(*self.op_args, **self.op_kwargs)
  File "/opt/airflow/dags/ETL_psql/Load/Load_psql.py", line 38, in Load_schema
    conn = psycopg2.connect(**connect_params); # Connect
  File "/home/airflow/.local/lib/python3.7/site-packages/psycopg2/__init__.py", line 122, in connect
    conn = _connect(dsn, connection_factory=connection_factory, **kwasync)
psycopg2.OperationalError: connection to server at "localhost" (127.0.0.1), port 5432 failed: Connection refused
	Is the server running on that host and accepting TCP/IP connections?
connection to server at "localhost" (::1), port 5432 failed: Cannot assign requested address
	Is the server running on that host and accepting TCP/IP connections?

[2023-06-13T14:32:44.125+0000] {taskinstance.py:1323} INFO - Marking task as UP_FOR_RETRY. dag_id=ETL_psql_redshift_dag, task_id=Load_to_psql, execution_date=20230613T143224, start_date=20230613T143243, end_date=20230613T143244
[2023-06-13T14:32:44.132+0000] {standard_task_runner.py:105} ERROR - Failed to execute job 10 for task Load_to_psql (connection to server at "localhost" (127.0.0.1), port 5432 failed: Connection refused
	Is the server running on that host and accepting TCP/IP connections?
connection to server at "localhost" (::1), port 5432 failed: Cannot assign requested address
	Is the server running on that host and accepting TCP/IP connections?
; 318)
[2023-06-13T14:32:44.148+0000] {local_task_job.py:208} INFO - Task exited with return code 1
[2023-06-13T14:32:44.168+0000] {taskinstance.py:2578} INFO - 0 downstream tasks scheduled from follow-on schedule check
