[2023-06-12T18:10:41.573+0700] {taskinstance.py:1083} INFO - Dependencies all met for <TaskInstance: ETL_psql_redshift_dag.Load_to_psql scheduled__2023-06-11T00:00:00+00:00 [queued]>
[2023-06-12T18:10:41.578+0700] {taskinstance.py:1083} INFO - Dependencies all met for <TaskInstance: ETL_psql_redshift_dag.Load_to_psql scheduled__2023-06-11T00:00:00+00:00 [queued]>
[2023-06-12T18:10:41.579+0700] {taskinstance.py:1279} INFO - 
--------------------------------------------------------------------------------
[2023-06-12T18:10:41.579+0700] {taskinstance.py:1280} INFO - Starting attempt 3 of 3
[2023-06-12T18:10:41.579+0700] {taskinstance.py:1281} INFO - 
--------------------------------------------------------------------------------
[2023-06-12T18:10:41.585+0700] {taskinstance.py:1300} INFO - Executing <Task(PythonOperator): Load_to_psql> on 2023-06-11 00:00:00+00:00
[2023-06-12T18:10:41.587+0700] {standard_task_runner.py:55} INFO - Started process 14584 to run task
[2023-06-12T18:10:41.590+0700] {standard_task_runner.py:82} INFO - Running: ['airflow', 'tasks', 'run', 'ETL_psql_redshift_dag', 'Load_to_psql', 'scheduled__2023-06-11T00:00:00+00:00', '--job-id', '39', '--raw', '--subdir', 'DAGS_FOLDER/dags_setup.py', '--cfg-path', '/var/folders/13/nw165ws91y30x7r8_6b34m_m0000gn/T/tmpxbvf1rlr']
[2023-06-12T18:10:41.591+0700] {standard_task_runner.py:83} INFO - Job 39: Subtask Load_to_psql
[2023-06-12T18:10:41.641+0700] {task_command.py:388} INFO - Running <TaskInstance: ETL_psql_redshift_dag.Load_to_psql scheduled__2023-06-11T00:00:00+00:00 [running]> on host vus-macbook-pro.local
[2023-06-12T18:10:41.686+0700] {taskinstance.py:1507} INFO - Exporting the following env vars:
AIRFLOW_CTX_DAG_OWNER=vupham
AIRFLOW_CTX_DAG_ID=ETL_psql_redshift_dag
AIRFLOW_CTX_TASK_ID=Load_to_psql
AIRFLOW_CTX_EXECUTION_DATE=2023-06-11T00:00:00+00:00
AIRFLOW_CTX_TRY_NUMBER=3
AIRFLOW_CTX_DAG_RUN_ID=scheduled__2023-06-11T00:00:00+00:00
[2023-06-12T18:14:39.223+0700] {local_task_job.py:272} WARNING - State of this instance has been externally set to None. Terminating instance.
[2023-06-12T18:14:39.230+0700] {process_utils.py:129} INFO - Sending Signals.SIGTERM to group 14584. PIDs of all processes in the group: [14584]
[2023-06-12T18:14:39.230+0700] {process_utils.py:84} INFO - Sending the signal Signals.SIGTERM to group 14584
[2023-06-12T18:14:39.230+0700] {taskinstance.py:1479} ERROR - Received SIGTERM. Terminating subprocesses.
[2023-06-12T18:14:39.243+0700] {taskinstance.py:1768} ERROR - Task failed with exception
Traceback (most recent call last):
  File "/opt/homebrew/lib/python3.10/site-packages/airflow/operators/python.py", line 175, in execute
    return_value = self.execute_callable()
  File "/opt/homebrew/lib/python3.10/site-packages/airflow/operators/python.py", line 192, in execute_callable
    return self.python_callable(*self.op_args, **self.op_kwargs)
  File "/Users/vupham/Desktop/DE_Project/dags/ETL_psql/Load/Load_psql.py", line 49, in Load_schema
    while (os.path.isfile(filePath) != True) : time.sleep(3);
  File "/opt/homebrew/lib/python3.10/site-packages/airflow/models/taskinstance.py", line 1481, in signal_handler
    raise AirflowException("Task received SIGTERM signal")
airflow.exceptions.AirflowException: Task received SIGTERM signal
[2023-06-12T18:14:39.247+0700] {taskinstance.py:1318} INFO - Marking task as FAILED. dag_id=ETL_psql_redshift_dag, task_id=Load_to_psql, execution_date=20230611T000000, start_date=20230612T111041, end_date=20230612T111439
[2023-06-12T18:14:39.260+0700] {standard_task_runner.py:100} ERROR - Failed to execute job 39 for task Load_to_psql ((psycopg2.errors.ForeignKeyViolation) insert or update on table "task_fail" violates foreign key constraint "task_fail_ti_fkey"
DETAIL:  Key (dag_id, task_id, run_id, map_index)=(ETL_psql_redshift_dag, Load_to_psql, scheduled__2023-06-11T00:00:00+00:00, -1) is not present in table "task_instance".

[SQL: INSERT INTO task_fail (task_id, dag_id, run_id, map_index, start_date, end_date, duration) VALUES (%(task_id)s, %(dag_id)s, %(run_id)s, %(map_index)s, %(start_date)s, %(end_date)s, %(duration)s) RETURNING task_fail.id]
[parameters: {'task_id': 'Load_to_psql', 'dag_id': 'ETL_psql_redshift_dag', 'run_id': 'scheduled__2023-06-11T00:00:00+00:00', 'map_index': -1, 'start_date': datetime.datetime(2023, 6, 12, 11, 10, 41, 573352, tzinfo=Timezone('UTC')), 'end_date': datetime.datetime(2023, 6, 12, 11, 14, 39, 247057, tzinfo=Timezone('UTC')), 'duration': 237}]
(Background on this error at: https://sqlalche.me/e/14/gkpj); 14584)
[2023-06-12T18:14:39.292+0700] {process_utils.py:79} INFO - Process psutil.Process(pid=14584, status='terminated', exitcode=1, started='18:10:41') (14584) terminated with exit code 1
