[2023-06-13T14:42:29.173+0000] {taskinstance.py:1083} INFO - Dependencies all met for <TaskInstance: ETL_psql_redshift_dag.Load_to_psql manual__2023-06-13T14:40:09.208875+00:00 [queued]>
[2023-06-13T14:42:29.178+0000] {taskinstance.py:1083} INFO - Dependencies all met for <TaskInstance: ETL_psql_redshift_dag.Load_to_psql manual__2023-06-13T14:40:09.208875+00:00 [queued]>
[2023-06-13T14:42:29.179+0000] {taskinstance.py:1279} INFO - 
--------------------------------------------------------------------------------
[2023-06-13T14:42:29.179+0000] {taskinstance.py:1280} INFO - Starting attempt 2 of 3
[2023-06-13T14:42:29.180+0000] {taskinstance.py:1281} INFO - 
--------------------------------------------------------------------------------
[2023-06-13T14:42:29.186+0000] {taskinstance.py:1300} INFO - Executing <Task(PythonOperator): Load_to_psql> on 2023-06-13 14:40:09.208875+00:00
[2023-06-13T14:42:29.192+0000] {standard_task_runner.py:55} INFO - Started process 258 to run task
[2023-06-13T14:42:29.196+0000] {standard_task_runner.py:82} INFO - Running: ['***', 'tasks', 'run', 'ETL_psql_redshift_dag', 'Load_to_psql', 'manual__2023-06-13T14:40:09.208875+00:00', '--job-id', '9', '--raw', '--subdir', 'DAGS_FOLDER/dags_setup.py', '--cfg-path', '/tmp/tmp1y8piwcr']
[2023-06-13T14:42:29.199+0000] {standard_task_runner.py:83} INFO - Job 9: Subtask Load_to_psql
[2023-06-13T14:42:29.249+0000] {task_command.py:388} INFO - Running <TaskInstance: ETL_psql_redshift_dag.Load_to_psql manual__2023-06-13T14:40:09.208875+00:00 [running]> on host 63f0fed3274d
[2023-06-13T14:42:29.294+0000] {taskinstance.py:1509} INFO - Exporting the following env vars:
AIRFLOW_CTX_DAG_OWNER=vupham
AIRFLOW_CTX_DAG_ID=ETL_psql_redshift_dag
AIRFLOW_CTX_TASK_ID=Load_to_psql
AIRFLOW_CTX_EXECUTION_DATE=2023-06-13T14:40:09.208875+00:00
AIRFLOW_CTX_TRY_NUMBER=2
AIRFLOW_CTX_DAG_RUN_ID=manual__2023-06-13T14:40:09.208875+00:00
[2023-06-13T14:42:29.296+0000] {taskinstance.py:1768} ERROR - Task failed with exception
Traceback (most recent call last):
  File "/home/airflow/.local/lib/python3.7/site-packages/airflow/operators/python.py", line 175, in execute
    return_value = self.execute_callable()
  File "/home/airflow/.local/lib/python3.7/site-packages/airflow/operators/python.py", line 192, in execute_callable
    return self.python_callable(*self.op_args, **self.op_kwargs)
  File "/opt/airflow/dags/ETL_psql/Load/Load_psql.py", line 38, in Load_schema
    conn = psycopg2.connect(**connect_params); # Connect
  File "/home/airflow/.local/lib/python3.7/site-packages/psycopg2/__init__.py", line 122, in connect
    conn = _connect(dsn, connection_factory=connection_factory, **kwasync)
psycopg2.OperationalError: connection to server at "localhost" (127.0.0.1), port 5432 failed: Connection refused
	Is the server running on that host and accepting TCP/IP connections?
connection to server at "localhost" (::1), port 5432 failed: Cannot assign requested address
	Is the server running on that host and accepting TCP/IP connections?

[2023-06-13T14:42:29.304+0000] {taskinstance.py:1323} INFO - Marking task as UP_FOR_RETRY. dag_id=ETL_psql_redshift_dag, task_id=Load_to_psql, execution_date=20230613T144009, start_date=20230613T144229, end_date=20230613T144229
[2023-06-13T14:42:29.310+0000] {standard_task_runner.py:105} ERROR - Failed to execute job 9 for task Load_to_psql (connection to server at "localhost" (127.0.0.1), port 5432 failed: Connection refused
	Is the server running on that host and accepting TCP/IP connections?
connection to server at "localhost" (::1), port 5432 failed: Cannot assign requested address
	Is the server running on that host and accepting TCP/IP connections?
; 258)
[2023-06-13T14:42:29.328+0000] {local_task_job.py:208} INFO - Task exited with return code 1
[2023-06-13T14:42:29.345+0000] {taskinstance.py:2578} INFO - 0 downstream tasks scheduled from follow-on schedule check
