[2023-06-14T09:13:07.648+0000] {taskinstance.py:1083} INFO - Dependencies all met for <TaskInstance: ETL_psql_redshift_dag.Load_to_psql scheduled__2023-06-13T00:00:00+00:00 [queued]>
[2023-06-14T09:13:07.654+0000] {taskinstance.py:1083} INFO - Dependencies all met for <TaskInstance: ETL_psql_redshift_dag.Load_to_psql scheduled__2023-06-13T00:00:00+00:00 [queued]>
[2023-06-14T09:13:07.655+0000] {taskinstance.py:1279} INFO - 
--------------------------------------------------------------------------------
[2023-06-14T09:13:07.655+0000] {taskinstance.py:1280} INFO - Starting attempt 1 of 3
[2023-06-14T09:13:07.656+0000] {taskinstance.py:1281} INFO - 
--------------------------------------------------------------------------------
[2023-06-14T09:13:07.663+0000] {taskinstance.py:1300} INFO - Executing <Task(PythonOperator): Load_to_psql> on 2023-06-13 00:00:00+00:00
[2023-06-14T09:13:07.669+0000] {standard_task_runner.py:55} INFO - Started process 367 to run task
[2023-06-14T09:13:07.672+0000] {standard_task_runner.py:82} INFO - Running: ['***', 'tasks', 'run', 'ETL_psql_redshift_dag', 'Load_to_psql', 'scheduled__2023-06-13T00:00:00+00:00', '--job-id', '19', '--raw', '--subdir', 'DAGS_FOLDER/dags_setup.py', '--cfg-path', '/tmp/tmp8f_5li11']
[2023-06-14T09:13:07.674+0000] {standard_task_runner.py:83} INFO - Job 19: Subtask Load_to_psql
[2023-06-14T09:13:07.725+0000] {task_command.py:388} INFO - Running <TaskInstance: ETL_psql_redshift_dag.Load_to_psql scheduled__2023-06-13T00:00:00+00:00 [running]> on host f2da7a3b6ffa
[2023-06-14T09:13:07.770+0000] {taskinstance.py:1509} INFO - Exporting the following env vars:
AIRFLOW_CTX_DAG_OWNER=vupham
AIRFLOW_CTX_DAG_ID=ETL_psql_redshift_dag
AIRFLOW_CTX_TASK_ID=Load_to_psql
AIRFLOW_CTX_EXECUTION_DATE=2023-06-13T00:00:00+00:00
AIRFLOW_CTX_TRY_NUMBER=1
AIRFLOW_CTX_DAG_RUN_ID=scheduled__2023-06-13T00:00:00+00:00
[2023-06-14T09:13:07.859+0000] {taskinstance.py:1768} ERROR - Task failed with exception
Traceback (most recent call last):
  File "/home/airflow/.local/lib/python3.7/site-packages/airflow/operators/python.py", line 175, in execute
    return_value = self.execute_callable()
  File "/home/airflow/.local/lib/python3.7/site-packages/airflow/operators/python.py", line 192, in execute_callable
    return self.python_callable(*self.op_args, **self.op_kwargs)
  File "/opt/airflow/dags/ETL_psql/Load/Load_psql.py", line 53, in Load_schema
    Load_table(f"Sale_schema.{table}", df, cur);
  File "/opt/airflow/dags/ETL_psql/Load/Load_psql.py", line 23, in Load_table
    cur.executemany(query, records);
psycopg2.errors.UniqueViolation: duplicate key value violates unique constraint "locations_pkey"
DETAIL:  Key (postal_code)=(39980) already exists.

[2023-06-14T09:13:07.869+0000] {taskinstance.py:1323} INFO - Marking task as UP_FOR_RETRY. dag_id=ETL_psql_redshift_dag, task_id=Load_to_psql, execution_date=20230613T000000, start_date=20230614T091307, end_date=20230614T091307
[2023-06-14T09:13:07.876+0000] {standard_task_runner.py:105} ERROR - Failed to execute job 19 for task Load_to_psql (duplicate key value violates unique constraint "locations_pkey"
DETAIL:  Key (postal_code)=(39980) already exists.
; 367)
[2023-06-14T09:13:07.924+0000] {local_task_job.py:208} INFO - Task exited with return code 1
[2023-06-14T09:13:07.942+0000] {taskinstance.py:2578} INFO - 0 downstream tasks scheduled from follow-on schedule check
