[2023-06-14T12:45:50.041+0000] {taskinstance.py:1083} INFO - Dependencies all met for <TaskInstance: ETL_psql_redshift_dag.Load_to_psql manual__2023-06-14T12:39:30.349993+00:00 [queued]>
[2023-06-14T12:45:50.049+0000] {taskinstance.py:1083} INFO - Dependencies all met for <TaskInstance: ETL_psql_redshift_dag.Load_to_psql manual__2023-06-14T12:39:30.349993+00:00 [queued]>
[2023-06-14T12:45:50.050+0000] {taskinstance.py:1279} INFO - 
--------------------------------------------------------------------------------
[2023-06-14T12:45:50.051+0000] {taskinstance.py:1280} INFO - Starting attempt 2 of 3
[2023-06-14T12:45:50.051+0000] {taskinstance.py:1281} INFO - 
--------------------------------------------------------------------------------
[2023-06-14T12:45:50.058+0000] {taskinstance.py:1300} INFO - Executing <Task(PythonOperator): Load_to_psql> on 2023-06-14 12:39:30.349993+00:00
[2023-06-14T12:45:50.065+0000] {standard_task_runner.py:55} INFO - Started process 348 to run task
[2023-06-14T12:45:50.068+0000] {standard_task_runner.py:82} INFO - Running: ['***', 'tasks', 'run', 'ETL_psql_redshift_dag', 'Load_to_psql', 'manual__2023-06-14T12:39:30.349993+00:00', '--job-id', '10', '--raw', '--subdir', 'DAGS_FOLDER/dags_setup.py', '--cfg-path', '/tmp/tmpdwm324g7']
[2023-06-14T12:45:50.070+0000] {standard_task_runner.py:83} INFO - Job 10: Subtask Load_to_psql
[2023-06-14T12:45:50.129+0000] {task_command.py:388} INFO - Running <TaskInstance: ETL_psql_redshift_dag.Load_to_psql manual__2023-06-14T12:39:30.349993+00:00 [running]> on host 3d4df578486c
[2023-06-14T12:45:50.180+0000] {taskinstance.py:1509} INFO - Exporting the following env vars:
AIRFLOW_CTX_DAG_OWNER=vupham
AIRFLOW_CTX_DAG_ID=ETL_psql_redshift_dag
AIRFLOW_CTX_TASK_ID=Load_to_psql
AIRFLOW_CTX_EXECUTION_DATE=2023-06-14T12:39:30.349993+00:00
AIRFLOW_CTX_TRY_NUMBER=2
AIRFLOW_CTX_DAG_RUN_ID=manual__2023-06-14T12:39:30.349993+00:00
[2023-06-14T12:45:50.274+0000] {taskinstance.py:1768} ERROR - Task failed with exception
Traceback (most recent call last):
  File "/home/airflow/.local/lib/python3.7/site-packages/airflow/operators/python.py", line 175, in execute
    return_value = self.execute_callable()
  File "/home/airflow/.local/lib/python3.7/site-packages/airflow/operators/python.py", line 192, in execute_callable
    return self.python_callable(*self.op_args, **self.op_kwargs)
  File "/opt/airflow/dags/ETL_psql/Load/Load_psql.py", line 53, in Load_schema
    Load_table(f"Sale_schema.{table}", df, cur);
  File "/opt/airflow/dags/ETL_psql/Load/Load_psql.py", line 23, in Load_table
    cur.executemany(query, records);
psycopg2.errors.UniqueViolation: duplicate key value violates unique constraint "locations_pkey"
DETAIL:  Key (postal_code)=(39980) already exists.

[2023-06-14T12:45:50.284+0000] {taskinstance.py:1323} INFO - Marking task as UP_FOR_RETRY. dag_id=ETL_psql_redshift_dag, task_id=Load_to_psql, execution_date=20230614T123930, start_date=20230614T124550, end_date=20230614T124550
[2023-06-14T12:45:50.291+0000] {standard_task_runner.py:105} ERROR - Failed to execute job 10 for task Load_to_psql (duplicate key value violates unique constraint "locations_pkey"
DETAIL:  Key (postal_code)=(39980) already exists.
; 348)
[2023-06-14T12:45:50.321+0000] {local_task_job.py:208} INFO - Task exited with return code 1
[2023-06-14T12:45:50.338+0000] {taskinstance.py:2578} INFO - 0 downstream tasks scheduled from follow-on schedule check
